{
 "cells": [
  {
   "cell_type": "code",
   "execution_count": 11,
   "id": "cb776f2f-a1ca-41f6-bbf0-1fdf5edd0148",
   "metadata": {},
   "outputs": [],
   "source": [
    "import tensorflow as tf\n",
    "from tensorflow import keras as ke\n",
    "import numpy as np"
   ]
  },
  {
   "cell_type": "code",
   "execution_count": 12,
   "id": "80f423b6-0386-44c9-885f-5291d34776c3",
   "metadata": {},
   "outputs": [],
   "source": [
    "model1 = ke.Sequential()\n",
    "model2 = ke.Sequential()\n",
    "\n",
    "h_layer = ke.layers.Dense(100)\n",
    "\n",
    "I1 = ke.layers.InputLayer(input_shape = (1,))\n",
    "I2 = ke.layers.InputLayer(input_shape = (1,))\n",
    "\n",
    "out1 = ke.layers.Dense(1,activation='sigmoid')\n",
    "out2 = ke.layers.Dense(1,activation='sigmoid')"
   ]
  },
  {
   "cell_type": "code",
   "execution_count": 13,
   "id": "367acdac-b06f-498e-bfed-786b40006fa7",
   "metadata": {},
   "outputs": [],
   "source": [
    "model1.add(I1)\n",
    "model1.add(h_layer)\n",
    "model1.add(out1)\n",
    "\n",
    "model2.add(I2)\n",
    "model2.add(h_layer)\n",
    "model2.add(out2)"
   ]
  },
  {
   "cell_type": "code",
   "execution_count": 15,
   "id": "52c579ce-76bc-431d-a758-c573c9f7d471",
   "metadata": {},
   "outputs": [
    {
     "name": "stderr",
     "output_type": "stream",
     "text": [
      "2023-07-12 15:19:39.308887: W tensorflow/core/framework/op_kernel.cc:1830] OP_REQUIRES failed at matmul_op_impl.h:621 : INTERNAL: the function failed to launch on the GPU\n",
      "2023-07-12 15:19:39.308929: I tensorflow/core/common_runtime/executor.cc:1197] [/job:localhost/replica:0/task:0/device:GPU:0] (DEBUG INFO) Executor start aborting (this does not indicate an error and you can ignore this message): INTERNAL: the function failed to launch on the GPU\n",
      "\t [[{{node sequential_4/dense_4/MatMul}}]]\n"
     ]
    },
    {
     "ename": "InternalError",
     "evalue": "Graph execution error:\n\nDetected at node 'sequential_4/dense_4/MatMul' defined at (most recent call last):\n    File \"/home/yashraj18422/miniconda3/envs/tf2parth/lib/python3.9/runpy.py\", line 197, in _run_module_as_main\n      return _run_code(code, main_globals, None,\n    File \"/home/yashraj18422/miniconda3/envs/tf2parth/lib/python3.9/runpy.py\", line 87, in _run_code\n      exec(code, run_globals)\n    File \"/home/yashraj18422/miniconda3/envs/tf2parth/lib/python3.9/site-packages/ipykernel_launcher.py\", line 17, in <module>\n      app.launch_new_instance()\n    File \"/home/yashraj18422/miniconda3/envs/tf2parth/lib/python3.9/site-packages/traitlets/config/application.py\", line 992, in launch_instance\n      app.start()\n    File \"/home/yashraj18422/miniconda3/envs/tf2parth/lib/python3.9/site-packages/ipykernel/kernelapp.py\", line 711, in start\n      self.io_loop.start()\n    File \"/home/yashraj18422/miniconda3/envs/tf2parth/lib/python3.9/site-packages/tornado/platform/asyncio.py\", line 215, in start\n      self.asyncio_loop.run_forever()\n    File \"/home/yashraj18422/miniconda3/envs/tf2parth/lib/python3.9/asyncio/base_events.py\", line 601, in run_forever\n      self._run_once()\n    File \"/home/yashraj18422/miniconda3/envs/tf2parth/lib/python3.9/asyncio/base_events.py\", line 1905, in _run_once\n      handle._run()\n    File \"/home/yashraj18422/miniconda3/envs/tf2parth/lib/python3.9/asyncio/events.py\", line 80, in _run\n      self._context.run(self._callback, *self._args)\n    File \"/home/yashraj18422/miniconda3/envs/tf2parth/lib/python3.9/site-packages/ipykernel/kernelbase.py\", line 510, in dispatch_queue\n      await self.process_one()\n    File \"/home/yashraj18422/miniconda3/envs/tf2parth/lib/python3.9/site-packages/ipykernel/kernelbase.py\", line 499, in process_one\n      await dispatch(*args)\n    File \"/home/yashraj18422/miniconda3/envs/tf2parth/lib/python3.9/site-packages/ipykernel/kernelbase.py\", line 406, in dispatch_shell\n      await result\n    File \"/home/yashraj18422/miniconda3/envs/tf2parth/lib/python3.9/site-packages/ipykernel/kernelbase.py\", line 729, in execute_request\n      reply_content = await reply_content\n    File \"/home/yashraj18422/miniconda3/envs/tf2parth/lib/python3.9/site-packages/ipykernel/ipkernel.py\", line 411, in do_execute\n      res = shell.run_cell(\n    File \"/home/yashraj18422/miniconda3/envs/tf2parth/lib/python3.9/site-packages/ipykernel/zmqshell.py\", line 531, in run_cell\n      return super().run_cell(*args, **kwargs)\n    File \"/home/yashraj18422/miniconda3/envs/tf2parth/lib/python3.9/site-packages/IPython/core/interactiveshell.py\", line 2945, in run_cell\n      result = self._run_cell(\n    File \"/home/yashraj18422/miniconda3/envs/tf2parth/lib/python3.9/site-packages/IPython/core/interactiveshell.py\", line 3000, in _run_cell\n      return runner(coro)\n    File \"/home/yashraj18422/miniconda3/envs/tf2parth/lib/python3.9/site-packages/IPython/core/async_helpers.py\", line 129, in _pseudo_sync_runner\n      coro.send(None)\n    File \"/home/yashraj18422/miniconda3/envs/tf2parth/lib/python3.9/site-packages/IPython/core/interactiveshell.py\", line 3203, in run_cell_async\n      has_raised = await self.run_ast_nodes(code_ast.body, cell_name,\n    File \"/home/yashraj18422/miniconda3/envs/tf2parth/lib/python3.9/site-packages/IPython/core/interactiveshell.py\", line 3382, in run_ast_nodes\n      if await self.run_code(code, result, async_=asy):\n    File \"/home/yashraj18422/miniconda3/envs/tf2parth/lib/python3.9/site-packages/IPython/core/interactiveshell.py\", line 3442, in run_code\n      exec(code_obj, self.user_global_ns, self.user_ns)\n    File \"/tmp/ipykernel_865585/4170656530.py\", line 1, in <module>\n      model1.predict(np.array([[1]]))\n    File \"/home/yashraj18422/miniconda3/envs/tf2parth/lib/python3.9/site-packages/keras/utils/traceback_utils.py\", line 65, in error_handler\n      return fn(*args, **kwargs)\n    File \"/home/yashraj18422/miniconda3/envs/tf2parth/lib/python3.9/site-packages/keras/engine/training.py\", line 2382, in predict\n      tmp_batch_outputs = self.predict_function(iterator)\n    File \"/home/yashraj18422/miniconda3/envs/tf2parth/lib/python3.9/site-packages/keras/engine/training.py\", line 2169, in predict_function\n      return step_function(self, iterator)\n    File \"/home/yashraj18422/miniconda3/envs/tf2parth/lib/python3.9/site-packages/keras/engine/training.py\", line 2155, in step_function\n      outputs = model.distribute_strategy.run(run_step, args=(data,))\n    File \"/home/yashraj18422/miniconda3/envs/tf2parth/lib/python3.9/site-packages/keras/engine/training.py\", line 2143, in run_step\n      outputs = model.predict_step(data)\n    File \"/home/yashraj18422/miniconda3/envs/tf2parth/lib/python3.9/site-packages/keras/engine/training.py\", line 2111, in predict_step\n      return self(x, training=False)\n    File \"/home/yashraj18422/miniconda3/envs/tf2parth/lib/python3.9/site-packages/keras/utils/traceback_utils.py\", line 65, in error_handler\n      return fn(*args, **kwargs)\n    File \"/home/yashraj18422/miniconda3/envs/tf2parth/lib/python3.9/site-packages/keras/engine/training.py\", line 558, in __call__\n      return super().__call__(*args, **kwargs)\n    File \"/home/yashraj18422/miniconda3/envs/tf2parth/lib/python3.9/site-packages/keras/utils/traceback_utils.py\", line 65, in error_handler\n      return fn(*args, **kwargs)\n    File \"/home/yashraj18422/miniconda3/envs/tf2parth/lib/python3.9/site-packages/keras/engine/base_layer.py\", line 1145, in __call__\n      outputs = call_fn(inputs, *args, **kwargs)\n    File \"/home/yashraj18422/miniconda3/envs/tf2parth/lib/python3.9/site-packages/keras/utils/traceback_utils.py\", line 96, in error_handler\n      return fn(*args, **kwargs)\n    File \"/home/yashraj18422/miniconda3/envs/tf2parth/lib/python3.9/site-packages/keras/engine/sequential.py\", line 412, in call\n      return super().call(inputs, training=training, mask=mask)\n    File \"/home/yashraj18422/miniconda3/envs/tf2parth/lib/python3.9/site-packages/keras/engine/functional.py\", line 512, in call\n      return self._run_internal_graph(inputs, training=training, mask=mask)\n    File \"/home/yashraj18422/miniconda3/envs/tf2parth/lib/python3.9/site-packages/keras/engine/functional.py\", line 669, in _run_internal_graph\n      outputs = node.layer(*args, **kwargs)\n    File \"/home/yashraj18422/miniconda3/envs/tf2parth/lib/python3.9/site-packages/keras/utils/traceback_utils.py\", line 65, in error_handler\n      return fn(*args, **kwargs)\n    File \"/home/yashraj18422/miniconda3/envs/tf2parth/lib/python3.9/site-packages/keras/engine/base_layer.py\", line 1145, in __call__\n      outputs = call_fn(inputs, *args, **kwargs)\n    File \"/home/yashraj18422/miniconda3/envs/tf2parth/lib/python3.9/site-packages/keras/utils/traceback_utils.py\", line 96, in error_handler\n      return fn(*args, **kwargs)\n    File \"/home/yashraj18422/miniconda3/envs/tf2parth/lib/python3.9/site-packages/keras/layers/core/dense.py\", line 241, in call\n      outputs = tf.matmul(a=inputs, b=self.kernel)\nNode: 'sequential_4/dense_4/MatMul'\nthe function failed to launch on the GPU\n\t [[{{node sequential_4/dense_4/MatMul}}]] [Op:__inference_predict_function_504]",
     "output_type": "error",
     "traceback": [
      "\u001b[0;31m---------------------------------------------------------------------------\u001b[0m",
      "\u001b[0;31mInternalError\u001b[0m                             Traceback (most recent call last)",
      "Cell \u001b[0;32mIn[15], line 1\u001b[0m\n\u001b[0;32m----> 1\u001b[0m \u001b[43mmodel1\u001b[49m\u001b[38;5;241;43m.\u001b[39;49m\u001b[43mpredict\u001b[49m\u001b[43m(\u001b[49m\u001b[43mnp\u001b[49m\u001b[38;5;241;43m.\u001b[39;49m\u001b[43marray\u001b[49m\u001b[43m(\u001b[49m\u001b[43m[\u001b[49m\u001b[43m[\u001b[49m\u001b[38;5;241;43m1\u001b[39;49m\u001b[43m]\u001b[49m\u001b[43m]\u001b[49m\u001b[43m)\u001b[49m\u001b[43m)\u001b[49m\n",
      "File \u001b[0;32m~/miniconda3/envs/tf2parth/lib/python3.9/site-packages/keras/utils/traceback_utils.py:70\u001b[0m, in \u001b[0;36mfilter_traceback.<locals>.error_handler\u001b[0;34m(*args, **kwargs)\u001b[0m\n\u001b[1;32m     67\u001b[0m     filtered_tb \u001b[38;5;241m=\u001b[39m _process_traceback_frames(e\u001b[38;5;241m.\u001b[39m__traceback__)\n\u001b[1;32m     68\u001b[0m     \u001b[38;5;66;03m# To get the full stack trace, call:\u001b[39;00m\n\u001b[1;32m     69\u001b[0m     \u001b[38;5;66;03m# `tf.debugging.disable_traceback_filtering()`\u001b[39;00m\n\u001b[0;32m---> 70\u001b[0m     \u001b[38;5;28;01mraise\u001b[39;00m e\u001b[38;5;241m.\u001b[39mwith_traceback(filtered_tb) \u001b[38;5;28;01mfrom\u001b[39;00m \u001b[38;5;28mNone\u001b[39m\n\u001b[1;32m     71\u001b[0m \u001b[38;5;28;01mfinally\u001b[39;00m:\n\u001b[1;32m     72\u001b[0m     \u001b[38;5;28;01mdel\u001b[39;00m filtered_tb\n",
      "File \u001b[0;32m~/miniconda3/envs/tf2parth/lib/python3.9/site-packages/tensorflow/python/eager/execute.py:52\u001b[0m, in \u001b[0;36mquick_execute\u001b[0;34m(op_name, num_outputs, inputs, attrs, ctx, name)\u001b[0m\n\u001b[1;32m     50\u001b[0m \u001b[38;5;28;01mtry\u001b[39;00m:\n\u001b[1;32m     51\u001b[0m   ctx\u001b[38;5;241m.\u001b[39mensure_initialized()\n\u001b[0;32m---> 52\u001b[0m   tensors \u001b[38;5;241m=\u001b[39m pywrap_tfe\u001b[38;5;241m.\u001b[39mTFE_Py_Execute(ctx\u001b[38;5;241m.\u001b[39m_handle, device_name, op_name,\n\u001b[1;32m     53\u001b[0m                                       inputs, attrs, num_outputs)\n\u001b[1;32m     54\u001b[0m \u001b[38;5;28;01mexcept\u001b[39;00m core\u001b[38;5;241m.\u001b[39m_NotOkStatusException \u001b[38;5;28;01mas\u001b[39;00m e:\n\u001b[1;32m     55\u001b[0m   \u001b[38;5;28;01mif\u001b[39;00m name \u001b[38;5;129;01mis\u001b[39;00m \u001b[38;5;129;01mnot\u001b[39;00m \u001b[38;5;28;01mNone\u001b[39;00m:\n",
      "\u001b[0;31mInternalError\u001b[0m: Graph execution error:\n\nDetected at node 'sequential_4/dense_4/MatMul' defined at (most recent call last):\n    File \"/home/yashraj18422/miniconda3/envs/tf2parth/lib/python3.9/runpy.py\", line 197, in _run_module_as_main\n      return _run_code(code, main_globals, None,\n    File \"/home/yashraj18422/miniconda3/envs/tf2parth/lib/python3.9/runpy.py\", line 87, in _run_code\n      exec(code, run_globals)\n    File \"/home/yashraj18422/miniconda3/envs/tf2parth/lib/python3.9/site-packages/ipykernel_launcher.py\", line 17, in <module>\n      app.launch_new_instance()\n    File \"/home/yashraj18422/miniconda3/envs/tf2parth/lib/python3.9/site-packages/traitlets/config/application.py\", line 992, in launch_instance\n      app.start()\n    File \"/home/yashraj18422/miniconda3/envs/tf2parth/lib/python3.9/site-packages/ipykernel/kernelapp.py\", line 711, in start\n      self.io_loop.start()\n    File \"/home/yashraj18422/miniconda3/envs/tf2parth/lib/python3.9/site-packages/tornado/platform/asyncio.py\", line 215, in start\n      self.asyncio_loop.run_forever()\n    File \"/home/yashraj18422/miniconda3/envs/tf2parth/lib/python3.9/asyncio/base_events.py\", line 601, in run_forever\n      self._run_once()\n    File \"/home/yashraj18422/miniconda3/envs/tf2parth/lib/python3.9/asyncio/base_events.py\", line 1905, in _run_once\n      handle._run()\n    File \"/home/yashraj18422/miniconda3/envs/tf2parth/lib/python3.9/asyncio/events.py\", line 80, in _run\n      self._context.run(self._callback, *self._args)\n    File \"/home/yashraj18422/miniconda3/envs/tf2parth/lib/python3.9/site-packages/ipykernel/kernelbase.py\", line 510, in dispatch_queue\n      await self.process_one()\n    File \"/home/yashraj18422/miniconda3/envs/tf2parth/lib/python3.9/site-packages/ipykernel/kernelbase.py\", line 499, in process_one\n      await dispatch(*args)\n    File \"/home/yashraj18422/miniconda3/envs/tf2parth/lib/python3.9/site-packages/ipykernel/kernelbase.py\", line 406, in dispatch_shell\n      await result\n    File \"/home/yashraj18422/miniconda3/envs/tf2parth/lib/python3.9/site-packages/ipykernel/kernelbase.py\", line 729, in execute_request\n      reply_content = await reply_content\n    File \"/home/yashraj18422/miniconda3/envs/tf2parth/lib/python3.9/site-packages/ipykernel/ipkernel.py\", line 411, in do_execute\n      res = shell.run_cell(\n    File \"/home/yashraj18422/miniconda3/envs/tf2parth/lib/python3.9/site-packages/ipykernel/zmqshell.py\", line 531, in run_cell\n      return super().run_cell(*args, **kwargs)\n    File \"/home/yashraj18422/miniconda3/envs/tf2parth/lib/python3.9/site-packages/IPython/core/interactiveshell.py\", line 2945, in run_cell\n      result = self._run_cell(\n    File \"/home/yashraj18422/miniconda3/envs/tf2parth/lib/python3.9/site-packages/IPython/core/interactiveshell.py\", line 3000, in _run_cell\n      return runner(coro)\n    File \"/home/yashraj18422/miniconda3/envs/tf2parth/lib/python3.9/site-packages/IPython/core/async_helpers.py\", line 129, in _pseudo_sync_runner\n      coro.send(None)\n    File \"/home/yashraj18422/miniconda3/envs/tf2parth/lib/python3.9/site-packages/IPython/core/interactiveshell.py\", line 3203, in run_cell_async\n      has_raised = await self.run_ast_nodes(code_ast.body, cell_name,\n    File \"/home/yashraj18422/miniconda3/envs/tf2parth/lib/python3.9/site-packages/IPython/core/interactiveshell.py\", line 3382, in run_ast_nodes\n      if await self.run_code(code, result, async_=asy):\n    File \"/home/yashraj18422/miniconda3/envs/tf2parth/lib/python3.9/site-packages/IPython/core/interactiveshell.py\", line 3442, in run_code\n      exec(code_obj, self.user_global_ns, self.user_ns)\n    File \"/tmp/ipykernel_865585/4170656530.py\", line 1, in <module>\n      model1.predict(np.array([[1]]))\n    File \"/home/yashraj18422/miniconda3/envs/tf2parth/lib/python3.9/site-packages/keras/utils/traceback_utils.py\", line 65, in error_handler\n      return fn(*args, **kwargs)\n    File \"/home/yashraj18422/miniconda3/envs/tf2parth/lib/python3.9/site-packages/keras/engine/training.py\", line 2382, in predict\n      tmp_batch_outputs = self.predict_function(iterator)\n    File \"/home/yashraj18422/miniconda3/envs/tf2parth/lib/python3.9/site-packages/keras/engine/training.py\", line 2169, in predict_function\n      return step_function(self, iterator)\n    File \"/home/yashraj18422/miniconda3/envs/tf2parth/lib/python3.9/site-packages/keras/engine/training.py\", line 2155, in step_function\n      outputs = model.distribute_strategy.run(run_step, args=(data,))\n    File \"/home/yashraj18422/miniconda3/envs/tf2parth/lib/python3.9/site-packages/keras/engine/training.py\", line 2143, in run_step\n      outputs = model.predict_step(data)\n    File \"/home/yashraj18422/miniconda3/envs/tf2parth/lib/python3.9/site-packages/keras/engine/training.py\", line 2111, in predict_step\n      return self(x, training=False)\n    File \"/home/yashraj18422/miniconda3/envs/tf2parth/lib/python3.9/site-packages/keras/utils/traceback_utils.py\", line 65, in error_handler\n      return fn(*args, **kwargs)\n    File \"/home/yashraj18422/miniconda3/envs/tf2parth/lib/python3.9/site-packages/keras/engine/training.py\", line 558, in __call__\n      return super().__call__(*args, **kwargs)\n    File \"/home/yashraj18422/miniconda3/envs/tf2parth/lib/python3.9/site-packages/keras/utils/traceback_utils.py\", line 65, in error_handler\n      return fn(*args, **kwargs)\n    File \"/home/yashraj18422/miniconda3/envs/tf2parth/lib/python3.9/site-packages/keras/engine/base_layer.py\", line 1145, in __call__\n      outputs = call_fn(inputs, *args, **kwargs)\n    File \"/home/yashraj18422/miniconda3/envs/tf2parth/lib/python3.9/site-packages/keras/utils/traceback_utils.py\", line 96, in error_handler\n      return fn(*args, **kwargs)\n    File \"/home/yashraj18422/miniconda3/envs/tf2parth/lib/python3.9/site-packages/keras/engine/sequential.py\", line 412, in call\n      return super().call(inputs, training=training, mask=mask)\n    File \"/home/yashraj18422/miniconda3/envs/tf2parth/lib/python3.9/site-packages/keras/engine/functional.py\", line 512, in call\n      return self._run_internal_graph(inputs, training=training, mask=mask)\n    File \"/home/yashraj18422/miniconda3/envs/tf2parth/lib/python3.9/site-packages/keras/engine/functional.py\", line 669, in _run_internal_graph\n      outputs = node.layer(*args, **kwargs)\n    File \"/home/yashraj18422/miniconda3/envs/tf2parth/lib/python3.9/site-packages/keras/utils/traceback_utils.py\", line 65, in error_handler\n      return fn(*args, **kwargs)\n    File \"/home/yashraj18422/miniconda3/envs/tf2parth/lib/python3.9/site-packages/keras/engine/base_layer.py\", line 1145, in __call__\n      outputs = call_fn(inputs, *args, **kwargs)\n    File \"/home/yashraj18422/miniconda3/envs/tf2parth/lib/python3.9/site-packages/keras/utils/traceback_utils.py\", line 96, in error_handler\n      return fn(*args, **kwargs)\n    File \"/home/yashraj18422/miniconda3/envs/tf2parth/lib/python3.9/site-packages/keras/layers/core/dense.py\", line 241, in call\n      outputs = tf.matmul(a=inputs, b=self.kernel)\nNode: 'sequential_4/dense_4/MatMul'\nthe function failed to launch on the GPU\n\t [[{{node sequential_4/dense_4/MatMul}}]] [Op:__inference_predict_function_504]"
     ]
    }
   ],
   "source": [
    "model1.predict(np.array([[1]]))"
   ]
  },
  {
   "cell_type": "code",
   "execution_count": null,
   "id": "f6a89c09-1f79-4558-abfd-4d2e24da1da7",
   "metadata": {},
   "outputs": [],
   "source": []
  }
 ],
 "metadata": {
  "kernelspec": {
   "display_name": "Python [conda env:tf2parth]",
   "language": "python",
   "name": "conda-env-tf2parth-py"
  },
  "language_info": {
   "codemirror_mode": {
    "name": "ipython",
    "version": 3
   },
   "file_extension": ".py",
   "mimetype": "text/x-python",
   "name": "python",
   "nbconvert_exporter": "python",
   "pygments_lexer": "ipython3",
   "version": "3.9.17"
  }
 },
 "nbformat": 4,
 "nbformat_minor": 5
}
